COUT002 23:28:24 GMT  ERROR: LOGGER NOT INITIALIZED:
COUT002 23:28:24 GMT  ERROR: 		Remote end closed connection
A matrix: 

[[0.2414 0.8974 0.8542 ... 0.3547 0.0558 0.7943]
 [0.2783 0.6546 0.7332 ... 0.7361 0.4599 0.9979]
 [0.5175 0.3047 0.9847 ... 0.9445 0.9857 0.5238]
 ...
 [0.0342 0.5459 0.0819 ... 0.8746 0.3289 0.0225]
 [0.1592 0.4281 0.1324 ... 0.2318 0.0155 0.5807]
 [0.3974 0.9803 0.5691 ... 0.1427 0.5506 0.834 ]]
B matrix: 

[[0.8154 0.1798 0.9402 ... 0.8447 0.8282 0.6796]
 [0.9678 0.6129 0.9657 ... 0.9052 0.228  0.4973]
 [0.5819 0.4311 0.6167 ... 0.6755 0.7927 0.6966]
 ...
 [0.9428 0.3782 0.9679 ... 0.4741 0.3276 0.5735]
 [0.2864 0.2262 0.8731 ... 0.1208 0.7843 0.8819]
 [0.1565 0.9357 0.546  ... 0.9757 0.9699 0.9432]]
RPC_SYNC DONE
C transfer done
Timestamps transfer done
[[4616.19   4623.942  4611.586  ... 4531.3823 4604.401  4641.6763]
 [4661.1714 4652.2793 4644.744  ... 4557.7656 4628.49   4718.144 ]
 [4610.969  4582.6064 4609.6255 ... 4523.9688 4563.8022 4654.1436]
 ...
 [4648.451  4633.716  4609.0537 ... 4547.4453 4617.283  4651.7373]
 [4630.524  4624.6875 4616.351  ... 4547.8296 4621.0264 4658.391 ]
 [4582.0405 4602.264  4579.829  ... 4479.4453 4542.5024 4618.898 ]]
[[4616.1865 4623.946  4611.5815 ... 4531.38   4604.424  4641.6714]
 [4661.164  4652.275  4644.7583 ... 4557.769  4628.4966 4718.1333]
 [4610.9683 4582.612  4609.617  ... 4523.962  4563.8086 4654.154 ]
 ...
 [4648.4507 4633.711  4609.0586 ... 4547.446  4617.275  4651.7285]
 [4630.5176 4624.6934 4616.3384 ... 4547.843  4621.0244 4658.3726]
 [4582.0317 4602.2764 4579.8276 ... 4479.44   4542.509  4618.8975]]
2219618.3788235295
Traceback (most recent call last):
  File "./run.py", line 170, in <module>
    np.testing.assert_allclose(C_expected, C, rtol=1e-05, atol=1e-06)
  File "/python/python-x86_64/lib/python3.8/site-packages/numpy/testing/_private/utils.py", line 1592, in assert_allclose
    assert_array_compare(compare, actual, desired, err_msg=str(err_msg),
  File "/cb/toolchains/buildroot/monolith-default/202403181828-238-5e1418a5/rootfs-x86_64/usr/lib/python3.8/contextlib.py", line 75, in inner
    return func(*args, **kwds)
  File "/python/python-x86_64/lib/python3.8/site-packages/numpy/testing/_private/utils.py", line 862, in assert_array_compare
    raise AssertionError(msg)
AssertionError: 
Not equal to tolerance rtol=1e-05, atol=1e-06

Mismatched elements: 253 / 338560000 (7.47e-05%)
Max absolute difference: 0.05908203
Max relative difference: 1.2872487e-05
 x: array([[4616.1865, 4623.946 , 4611.5815, ..., 4531.38  , 4604.424 ,
        4641.6714],
       [4661.164 , 4652.275 , 4644.7583, ..., 4557.769 , 4628.4966,...
 y: array([[4616.19  , 4623.942 , 4611.586 , ..., 4531.3823, 4604.401 ,
        4641.6763],
       [4661.1714, 4652.2793, 4644.744 , ..., 4557.7656, 4628.49  ,...
Program completed in: 00:04:30
