COUT002 02:37:10 GMT  ERROR: LOGGER NOT INITIALIZED:
COUT002 02:37:10 GMT  ERROR: 		Remote end closed connection
A matrix: 

[[0.0945 0.4079 0.5669 ... 0.9676 0.3352 0.8496]
 [0.3666 0.3813 0.5034 ... 0.7788 0.3902 0.1926]
 [0.0972 0.0854 0.5545 ... 0.1137 0.4447 0.7137]
 ...
 [0.9221 0.656  0.1881 ... 0.1227 0.034  0.6702]
 [0.6947 0.8258 0.9569 ... 0.7214 0.4079 0.2632]
 [0.0683 0.6094 0.0725 ... 0.6528 0.2082 0.7761]]
B matrix: 

[[0.5113 0.8659 0.7354 ... 0.4904 0.0172 0.7762]
 [0.6902 0.1628 0.9029 ... 0.7499 0.3251 0.6732]
 [0.4662 0.3209 0.4161 ... 0.8877 0.5671 0.2838]
 ...
 [0.1506 0.8436 0.8729 ... 0.2216 0.3019 0.1557]
 [0.7685 0.4301 0.2818 ... 0.4085 0.5156 0.3718]
 [0.1182 0.9191 0.7103 ... 0.5462 0.0505 0.9109]]
RPC_SYNC DONE
C transfer done
Timestamps transfer done
[[9.1545596e+03 9.1281270e+03 9.1107236e+03 ... 9.1339023e+03
  9.0611836e+03 9.1145576e+03]
 [9.1510498e+03 9.1486670e+03 9.1347852e+03 ... 9.1527520e+03
  9.0828750e+03 9.1284971e+03]
 [9.2139756e+03 9.2202559e+03 9.1648975e+03 ... 9.2113262e+03
  9.1212930e+03 9.2219121e+03]
 ...
 [9.2253516e+03 9.1886084e+03 9.1127627e+03 ... 9.2162598e+03
  9.0835176e+03 9.2099492e+03]
 [9.1778428e+03 9.1821582e+03 9.1174922e+03 ... 9.1693740e+03
  9.0975889e+03 9.1876914e+03]
 [9.1748516e+03 9.1313271e+03 9.1150703e+03 ... 4.2390579e-01
  1.5869846e-37 9.1474844e+03]]
[[9154.657 9128.143 9110.743 ... 9133.903 9061.191 9114.544]
 [9151.052 9148.689 9134.819 ... 9152.759 9082.914 9128.53 ]
 [9213.953 9220.211 9164.877 ... 9211.318 9121.302 9221.9  ]
 ...
 [9225.331 9188.607 9112.753 ... 9216.315 9083.533 9209.942]
 [9177.848 9182.157 9117.512 ... 9169.404 9097.658 9187.677]
 [9174.839 9131.322 9115.095 ... 9151.376 9061.481 9147.446]]
9339632.383529412
Traceback (most recent call last):
  File "./run.py", line 170, in <module>
    np.testing.assert_allclose(C_expected, C, rtol=1e-05, atol=1e-06)
  File "/python/python-x86_64/lib/python3.8/site-packages/numpy/testing/_private/utils.py", line 1592, in assert_allclose
    assert_array_compare(compare, actual, desired, err_msg=str(err_msg),
  File "/cb/toolchains/buildroot/monolith-default/202403181828-238-5e1418a5/rootfs-x86_64/usr/lib/python3.8/contextlib.py", line 75, in inner
    return func(*args, **kwds)
  File "/python/python-x86_64/lib/python3.8/site-packages/numpy/testing/_private/utils.py", line 862, in assert_array_compare
    raise AssertionError(msg)
AssertionError: 
Not equal to tolerance rtol=1e-05, atol=1e-06

Mismatched elements: 3177269 / 1339560000 (0.237%)
Max absolute difference: 9357.8125
Max relative difference: inf
 x: array([[9154.657, 9128.143, 9110.743, ..., 9133.903, 9061.191, 9114.544],
       [9151.052, 9148.689, 9134.819, ..., 9152.759, 9082.914, 9128.53 ],
       [9213.953, 9220.211, 9164.877, ..., 9211.318, 9121.302, 9221.9  ],...
 y: array([[9.154560e+03, 9.128127e+03, 9.110724e+03, ..., 9.133902e+03,
        9.061184e+03, 9.114558e+03],
       [9.151050e+03, 9.148667e+03, 9.134785e+03, ..., 9.152752e+03,...
Program completed in: 00:22:54
