COUT002 23:22:14 GMT  ERROR: LOGGER NOT INITIALIZED:
COUT002 23:22:14 GMT  ERROR: 		Remote end closed connection
A matrix: 

[[0.1519 0.7687 0.7277 ... 0.6215 0.152  0.6447]
 [0.0219 0.0967 0.1104 ... 0.419  0.6677 0.1353]
 [0.2908 0.7761 0.6868 ... 0.4201 0.7337 0.2995]
 ...
 [0.4738 0.5474 0.2252 ... 0.7762 0.8417 0.711 ]
 [0.2293 0.2846 0.7748 ... 0.469  0.7585 0.8673]
 [0.4251 0.5121 0.585  ... 0.9579 0.0515 0.672 ]]
B matrix: 

[[0.1323 0.4989 0.5397 ... 0.507  0.4709 0.5155]
 [0.2515 0.5443 0.8377 ... 0.5253 0.0529 0.8299]
 [0.9884 0.1635 0.4411 ... 0.1889 0.0058 0.2821]
 ...
 [0.9259 0.0152 0.1553 ... 0.6388 0.2512 0.7392]
 [0.7106 0.5536 0.8509 ... 0.7275 0.9773 0.5996]
 [0.2259 0.2584 0.9924 ... 0.9489 0.8081 0.3538]]
RPC_SYNC DONE
C transfer done
Timestamps transfer done
[[4616.956  4620.4873 4636.3706 ... 4663.2    4635.9907 4581.5293]
 [4587.3647 4615.5225 4572.7383 ... 4645.9424 4622.6655 4575.4863]
 [4591.2075 4628.4307 4617.7407 ... 4637.2153 4644.968  4595.2983]
 ...
 [4633.5054 4635.697  4616.3066 ... 4658.3726 4646.943  4570.03  ]
 [4598.2773 4608.4463 4574.6157 ... 4625.5166 4635.201  4557.921 ]
 [4571.0557 4612.7246 4581.7783 ... 4630.735  4635.4272 4555.8516]]
[[4616.964  4620.4946 4636.3765 ... 4663.2    4636.001  4581.5303]
 [4587.364  4615.5054 4572.738  ... 4645.9395 4622.6685 4575.4907]
 [4591.2095 4628.44   4617.7217 ... 4637.217  4644.975  4595.299 ]
 ...
 [4633.5195 4635.675  4616.315  ... 4658.367  4646.941  4570.03  ]
 [4598.288  4608.445  4574.6333 ... 4625.525  4635.2007 4557.918 ]
 [4571.0425 4612.722  4581.772  ... 4630.742  4635.4287 4555.842 ]]
2484619.3000000003
Traceback (most recent call last):
  File "./run.py", line 170, in <module>
    np.testing.assert_allclose(C_expected, C, rtol=1e-05, atol=1e-06)
  File "/python/python-x86_64/lib/python3.8/site-packages/numpy/testing/_private/utils.py", line 1592, in assert_allclose
    assert_array_compare(compare, actual, desired, err_msg=str(err_msg),
  File "/cb/toolchains/buildroot/monolith-default/202403181828-238-5e1418a5/rootfs-x86_64/usr/lib/python3.8/contextlib.py", line 75, in inner
    return func(*args, **kwds)
  File "/python/python-x86_64/lib/python3.8/site-packages/numpy/testing/_private/utils.py", line 862, in assert_array_compare
    raise AssertionError(msg)
AssertionError: 
Not equal to tolerance rtol=1e-05, atol=1e-06

Mismatched elements: 281 / 338560000 (8.3e-05%)
Max absolute difference: 0.05761719
Max relative difference: 1.2298304e-05
 x: array([[4616.964 , 4620.4946, 4636.3765, ..., 4663.2   , 4636.001 ,
        4581.5303],
       [4587.364 , 4615.5054, 4572.738 , ..., 4645.9395, 4622.6685,...
 y: array([[4616.956 , 4620.4873, 4636.3706, ..., 4663.2   , 4635.9907,
        4581.5293],
       [4587.3647, 4615.5225, 4572.7383, ..., 4645.9424, 4622.6655,...
Program completed in: 00:04:32
