COUT002 01:08:47 GMT  ERROR: LOGGER NOT INITIALIZED:
COUT002 01:08:47 GMT  ERROR: 		Remote end closed connection
A matrix: 

[[0.7215 0.9837 0.1591 ... 0.2675 0.3789 0.9365]
 [0.0021 0.743  0.7884 ... 0.8073 0.4971 0.2823]
 [0.1893 0.6771 0.8176 ... 0.8445 0.9188 0.0238]
 ...
 [0.021  0.5886 0.5571 ... 0.7374 0.3557 0.4408]
 [0.55   0.1713 0.1941 ... 0.7307 0.3414 0.9554]
 [0.6818 0.2645 0.9036 ... 0.3153 0.8615 0.4739]]
B matrix: 

[[0.1337 0.4773 0.4701 ... 0.9164 0.4277 0.5919]
 [0.6565 0.3684 0.4599 ... 0.8186 0.7345 0.3386]
 [0.9767 0.2406 0.6724 ... 0.5699 0.1124 0.6048]
 ...
 [0.9547 0.3756 0.8504 ... 0.4841 0.5095 0.9067]
 [0.9171 0.4111 0.1401 ... 0.599  0.5134 0.0208]
 [0.2534 0.0031 0.4726 ... 0.755  0.6497 0.9652]]
RPC_SYNC DONE
C transfer done
Timestamps transfer done
[[1.5373142e+03 1.5193333e+03 1.5308606e+03 ... 1.5240283e+03
  1.5389346e+03 1.5437524e+03]
 [1.5206266e+03 1.5119338e+03 1.5089755e+03 ... 1.5143872e+03
  1.5055814e+03 1.5139226e+03]
 [1.5307732e+03 1.5110387e+03 1.5214254e+03 ... 1.5042272e+03
  1.5035000e+03 1.5107854e+03]
 ...
 [1.5466661e+03 1.5371201e+03 1.5234724e+03 ... 1.5259868e+03
  1.5337689e+03 1.5499924e+03]
 [1.5163724e+03 1.4844814e+03 1.5085896e+03 ... 1.4975743e+03
  1.4919166e+03 1.4986686e+03]
 [1.5370995e+03 1.5270641e+03 1.5350706e+03 ... 4.4277248e+01
  4.9274715e+01 4.5740828e-01]]
[[1537.3153 1519.3318 1530.8596 ... 1524.0295 1538.9358 1543.7524]
 [1520.6304 1511.9375 1508.9778 ... 1514.3843 1505.5806 1513.9196]
 [1530.7758 1511.0391 1521.4254 ... 1504.2277 1503.5011 1510.7844]
 ...
 [1546.6667 1537.1215 1523.4738 ... 1525.989  1533.7731 1549.992 ]
 [1516.3728 1484.4805 1508.5918 ... 1497.5743 1491.916  1498.6636]
 [1537.0983 1527.0645 1535.0664 ... 1549.6917 1532.1052 1555.6571]]
276034.91411764704
Traceback (most recent call last):
  File "./run.py", line 170, in <module>
    np.testing.assert_allclose(C_expected, C, rtol=1e-05, atol=1e-06)
  File "/python/python-x86_64/lib/python3.8/site-packages/numpy/testing/_private/utils.py", line 1592, in assert_allclose
    assert_array_compare(compare, actual, desired, err_msg=str(err_msg),
  File "/cb/toolchains/buildroot/monolith-default/202403181828-238-5e1418a5/rootfs-x86_64/usr/lib/python3.8/contextlib.py", line 75, in inner
    return func(*args, **kwds)
  File "/python/python-x86_64/lib/python3.8/site-packages/numpy/testing/_private/utils.py", line 862, in assert_array_compare
    raise AssertionError(msg)
AssertionError: 
Not equal to tolerance rtol=1e-05, atol=1e-06

Mismatched elements: 60000 / 37210000 (0.161%)
Max absolute difference: 1589.9492
Max relative difference: 67586368.
 x: array([[1537.3153, 1519.3318, 1530.8596, ..., 1524.0295, 1538.9358,
        1543.7524],
       [1520.6304, 1511.9375, 1508.9778, ..., 1514.3843, 1505.5806,...
 y: array([[1.537314e+03, 1.519333e+03, 1.530861e+03, ..., 1.524028e+03,
        1.538935e+03, 1.543752e+03],
       [1.520627e+03, 1.511934e+03, 1.508975e+03, ..., 1.514387e+03,...
Program completed in: 00:01:34
